Workbook

Sheet nodes
A1: node | B1: x | C1: y | D1: z | E1: resx | F1: resy | G1: resz | H1: A | I1: mxp | J1: myp | K1: fzp | L1: mxs | M1: mys | N1: fzs | P1: N | Q1: NUM | R1: X | S1: Y | T1: Z | U1: RES | V1: NODE | W1: UX | X1: UY | Y1: UZ | Z1: F, | AA1: N | AB1: FY, | AC1: VALUE
A2: 1 | B2: 0 | C2: 0 | D2: 300 | E2: 1 | F2: 1 | G2: 1 | H2: 900 | I2: 0 | J2: 0 | K2: =-H2*4.25/10000 -> -0.3825 | L2: 0 | M2: 0 | N2: =-H2*2.5/10000 -> -0.225 | P2: N, | Q2: =A2&"," -> 1, | R2: =B2&"," -> 0, | S2: =C2&"," -> 0, | T2: =D2 -> 300 | U2: D, | V2: =A2&"," -> 1, | W2: =IF(E2=1,"UX","") -> UX | X2: =IF(F2=1,"UY","") -> UY | Y2: =IF(G2=1,"UY,","") -> UY, | Z2: F, | AA2: =Q2 -> 1, | AB2: FY, | AC2: =-(1.4*K2+1.5*N2) -> 0.873
A3: 2 | B3: 30 | C3: 0 | D3: 300 | E3: 0 | F3: 0 | G3: 1 | H3: 900 | I3: 0 | J3: 0 | K3: =-H3*4.25/10000 -> -0.3825 | L3: 0 | M3: 0 | N3: =-H3*2.5/10000 -> -0.225 | P3: N, | Q3: =A3&"," -> 2, | R3: =B3&"," -> 30, | S3: =C3&"," -> 0, | T3: =D3 -> 300 | U3: D, | V3: =A3&"," -> 2, | W3: =IF(E3=1,"UX","") | X3: =IF(F3=1,"UY","") | Y3: =IF(G3=1,"UY","") -> UY | Z3: F, | AA3: =Q3 -> 2, | AB3: FY, | AC3: =-(1.4*K3+1.5*N3) -> 0.873
A4: 3 | B4: 60 | C4: 0 | D4: 300 | E4: 0 | F4: 0 | G4: 1 | H4: 900 | I4: 0 | J4: 0 | K4: =-H4*4.25/10000 -> -0.3825 | L4: 0 | M4: 0 | N4: =-H4*2.5/10000 -> -0.225 | P4: N, | Q4: =A4&"," -> 3, | R4: =B4&"," -> 60, | S4: =C4&"," -> 0, | T4: =D4 -> 300 | U4: D, | V4: =A4&"," -> 3, | W4: =IF(E4=1,"UX","") | X4: =IF(F4=1,"UY","") | Y4: =IF(G4=1,"UY","") -> UY | Z4: F, | AA4: =Q4 -> 3, | AB4: FY, | AC4: =-(1.4*K4+1.5*N4) -> 0.873
A5: 4 | B5: 90 | C5: 0 | D5: 300 | E5: 0 | F5: 0 | G5: 1 | H5: 900 | I5: 0 | J5: 0 | K5: =-H5*4.25/10000 -> -0.3825 | L5: 0 | M5: 0 | N5: =-H5*2.5/10000 -> -0.225 | P5: N, | Q5: =A5&"," -> 4, | R5: =B5&"," -> 90, | S5: =C5&"," -> 0, | T5: =D5 -> 300 | U5: D, | V5: =A5&"," -> 4, | W5: =IF(E5=1,"UX","") | X5: =IF(F5=1,"UY","") | Y5: =IF(G5=1,"UY","") -> UY | Z5: F, | AA5: =Q5 -> 4, | AB5: FY, | AC5: =-(1.4*K5+1.5*N5) -> 0.873
A6: 5 | B6: 120 | C6: 0 | D6: 300 | E6: 0 | F6: 0 | G6: 1 | H6: 900 | I6: 0 | J6: 0 | K6: =-H6*4.25/10000 -> -0.3825 | L6: 0 | M6: 0 | N6: =-H6*2.5/10000 -> -0.225 | P6: N, | Q6: =A6&"," -> 5, | R6: =B6&"," -> 120, | S6: =C6&"," -> 0, | T6: =D6 -> 300 | U6: D, | V6: =A6&"," -> 5, | W6: =IF(E6=1,"UX","") | X6: =IF(F6=1,"UY","") | Y6: =IF(G6=1,"UY","") -> UY | Z6: F, | AA6: =Q6 -> 5, | AB6: FY, | AC6: =-(1.4*K6+1.5*N6) -> 0.873
A7: 6 | B7: 150 | C7: 0 | D7: 300 | E7: 0 | F7: 0 | G7: 1 | H7: 900 | I7: 0 | J7: 0 | K7: =-H7*4.25/10000 -> -0.3825 | L7: 0 | M7: 0 | N7: =-H7*2.5/10000 -> -0.225 | P7: N, | Q7: =A7&"," -> 6, | R7: =B7&"," -> 150, | S7: =C7&"," -> 0, | T7: =D7 -> 300 | U7: D, | V7: =A7&"," -> 6, | W7: =IF(E7=1,"UX","") | X7: =IF(F7=1,"UY","") | Y7: =IF(G7=1,"UY","") -> UY | Z7: F, | AA7: =Q7 -> 6, | AB7: FY, | AC7: =-(1.4*K7+1.5*N7) -> 0.873
A8: 7 | B8: 180 | C8: 0 | D8: 300 | E8: 0 | F8: 0 | G8: 1 | H8: 900 | I8: 0 | J8: 0 | K8: =-H8*4.25/10000 -> -0.3825 | L8: 0 | M8: 0 | N8: =-H8*2.5/10000 -> -0.225 | P8: N, | Q8: =A8&"," -> 7, | R8: =B8&"," -> 180, | S8: =C8&"," -> 0, | T8: =D8 -> 300 | U8: D, | V8: =A8&"," -> 7, | W8: =IF(E8=1,"UX","") | X8: =IF(F8=1,"UY","") | Y8: =IF(G8=1,"UY","") -> UY | Z8: F, | AA8: =Q8 -> 7, | AB8: FY, | AC8: =-(1.4*K8+1.5*N8) -> 0.873
A9: 8 | B9: 210 | C9: 0 | D9: 300 | E9: 0 | F9: 0 | G9: 1 | H9: 900 | I9: 0 | J9: 0 | K9: =-H9*4.25/10000 -> -0.3825 | L9: 0 | M9: 0 | N9: =-H9*2.5/10000 -> -0.225 | P9: N, | Q9: =A9&"," -> 8, | R9: =B9&"," -> 210, | S9: =C9&"," -> 0, | T9: =D9 -> 300 | U9: D, | V9: =A9&"," -> 8, | W9: =IF(E9=1,"UX","") | X9: =IF(F9=1,"UZ","") | Y9: =IF(G9=1,"UY","") -> UY | Z9: F, | AA9: =Q9 -> 8, | AB9: FY, | AC9: =-(1.4*K9+1.5*N9) -> 0.873
A10: 9 | B10: 240 | C10: 0 | D10: 300 | E10: 0 | F10: 0 | G10: 1 | H10: 900 | I10: 0 | J10: 0 | K10: =-H10*4.25/10000 -> -0.3825 | L10: 0 | M10: 0 | N10: =-H10*2.5/10000 -> -0.225 | P10: N, | Q10: =A10&"," -> 9, | R10: =B10&"," -> 240, | S10: =C10&"," -> 0, | T10: =D10 -> 300 | U10: D, | V10: =A10&"," -> 9, | W10: =IF(E10=1,"UX","") | X10: =IF(F10=1,"UZ","") | Y10: =IF(G10=1,"UY","") -> UY | Z10: F, | AA10: =Q10 -> 9, | AB10: FY, | AC10: =-(1.4*K10+1.5*N10) -> 0.873
A11: 10 | B11: 270 | C11: 0 | D11: 300 | E11: 0 | F11: 0 | G11: 1 | H11: 900 | I11: 0 | J11: 0 | K11: =-H11*4.25/10000 -> -0.3825 | L11: 0 | M11: 0 | N11: =-H11*2.5/10000 -> -0.225 | P11: N, | Q11: =A11&"," -> 10, | R11: =B11&"," -> 270, | S11: =C11&"," -> 0, | T11: =D11 -> 300 | U11: D, | V11: =A11&"," -> 10, | W11: =IF(E11=1,"UX","") | X11: =IF(F11=1,"UZ","") | Y11: =IF(G11=1,"UY","") -> UY | Z11: F, | AA11: =Q11 -> 10, | AB11: FY, | AC11: =-(1.4*K11+1.5*N11) -> 0.873
A12: 11 | B12: 300 | C12: 0 | D12: 300 | E12: 0 | F12: 0 | G12: 1 | H12: 900 | I12: 0 | J12: 0 | K12: =-H12*4.25/10000 -> -0.3825 | L12: 0 | M12: 0 | N12: =-H12*2.5/10000 -> -0.225 | P12: N, | Q12: =A12&"," -> 11, | R12: =B12&"," -> 300, | S12: =C12&"," -> 0, | T12: =D12 -> 300 | U12: D, | V12: =A12&"," -> 11, | W12: =IF(E12=1,"UX","") | X12: =IF(F12=1,"UY","") | Y12: =IF(G12=1,"UY","") -> UY | Z12: F, | AA12: =Q12 -> 11, | AB12: FY, | AC12: =-(1.4*K12+1.5*N12) -> 0.873
A13: 12 | B13: 330 | C13: 0 | D13: 300 | E13: 0 | F13: 0 | G13: 1 | H13: 900 | I13: 0 | J13: 0 | K13: =-H13*4.25/10000 -> -0.3825 | L13: 0 | M13: 0 | N13: =-H13*2.5/10000 -> -0.225 | P13: N, | Q13: =A13&"," -> 12, | R13: =B13&"," -> 330, | S13: =C13&"," -> 0, | T13: =D13 -> 300 | U13: D, | V13: =A13&"," -> 12, | W13: =IF(E13=1,"UX","") | X13: =IF(F13=1,"UY","") | Y13: =IF(G13=1,"UY","") -> UY | Z13: F, | AA13: =Q13 -> 12, | AB13: FY, | AC13: =-(1.4*K13+1.5*N13) -> 0.873
A14: 13 | B14: 360 | C14: 0 | D14: 300 | E14: 0 | F14: 0 | G14: 1 | H14: 900 | I14: 0 | J14: 0 | K14: =-H14*4.25/10000 -> -0.3825 | L14: 0 | M14: 0 | N14: =-H14*2.5/10000 -> -0.225 | P14: N, | Q14: =A14&"," -> 13, | R14: =B14&"," -> 360, | S14: =C14&"," -> 0, | T14: =D14 -> 300 | U14: D, | V14: =A14&"," -> 13, | W14: =IF(E14=1,"UX","") | X14: =IF(F14=1,"UY","") | Y14: =IF(G14=1,"UY","") -> UY | Z14: F, | AA14: =Q14 -> 13, | AB14: FY, | AC14: =-(1.4*K14+1.5*N14) -> 0.873
A15: 14 | B15: 390 | C15: 0 | D15: 300 | E15: 0 | F15: 0 | G15: 1 | H15: 900 | I15: 0 | J15: 0 | K15: =-H15*4.25/10000 -> -0.3825 | L15: 0 | M15: 0 | N15: =-H15*2.5/10000 -> -0.225 | P15: N, | Q15: =A15&"," -> 14, | R15: =B15&"," -> 390, | S15: =C15&"," -> 0, | T15: =D15 -> 300 | U15: D, | V15: =A15&"," -> 14, | W15: =IF(E15=1,"UX","") | X15: =IF(F15=1,"UY","") | Y15: =IF(G15=1,"UY","") -> UY | Z15: F, | AA15: =Q15 -> 14, | AB15: FY, | AC15: =-(1.4*K15+1.5*N15) -> 0.873
A16: 15 | B16: 420 | C16: 0 | D16: 300 | E16: 0 | F16: 0 | G16: 1 | H16: 900 | I16: 0 | J16: 0 | K16: =-H16*4.25/10000 -> -0.3825 | L16: 0 | M16: 0 | N16: =-H16*2.5/10000 -> -0.225 | P16: N, | Q16: =A16&"," -> 15, | R16: =B16&"," -> 420, | S16: =C16&"," -> 0, | T16: =D16 -> 300 | U16: D, | V16: =A16&"," -> 15, | W16: =IF(E16=1,"UX","") | X16: =IF(F16=1,"UY","") | Y16: =IF(G16=1,"UY","") -> UY | Z16: F, | AA16: =Q16 -> 15, | AB16: FY, | AC16: =-(1.4*K16+1.5*N16) -> 0.873
A17: 16 | B17: 450 | C17: 0 | D17: 300 | E17: 0 | F17: 0 | G17: 1 | H17: 900 | I17: 0 | J17: 0 | K17: =-H17*4.25/10000 -> -0.3825 | L17: 0 | M17: 0 | N17: =-H17*2.5/10000 -> -0.225 | P17: N, | Q17: =A17&"," -> 16, | R17: =B17&"," -> 450, | S17: =C17&"," -> 0, | T17: =D17 -> 300 | U17: D, | V17: =A17&"," -> 16, | W17: =IF(E17=1,"UX","") | X17: =IF(F17=1,"UY","") | Y17: =IF(G17=1,"UY","") -> UY | Z17: F, | AA17: =Q17 -> 16, | AB17: FY, | AC17: =-(1.4*K17+1.5*N17) -> 0.873
A18: 17 | B18: 480 | C18: 0 | D18: 300 | E18: 0 | F18: 0 | G18: 1 | H18: 900 | I18: 0 | J18: 0 | K18: =-H18*4.25/10000 -> -0.3825 | L18: 0 | M18: 0 | N18: =-H18*2.5/10000 -> -0.225 | P18: N, | Q18: =A18&"," -> 17, | R18: =B18&"," -> 480, | S18: =C18&"," -> 0, | T18: =D18 -> 300 | U18: D, | V18: =A18&"," -> 17, | W18: =IF(E18=1,"UX","") | X18: =IF(F18=1,"UY","") | Y18: =IF(G18=1,"UY","") -> UY | Z18: F, | AA18: =Q18 -> 17, | AB18: FY, | AC18: =-(1.4*K18+1.5*N18) -> 0.873
A19: 18 | B19: 510 | C19: 0 | D19: 300 | E19: 0 | F19: 0 | G19: 1 | H19: 900 | I19: 0 | J19: 0 | K19: =-H19*4.25/10000 -> -0.3825 | L19: 0 | M19: 0 | N19: =-H19*2.5/10000 -> -0.225 | P19: N, | Q19: =A19&"," -> 18, | R19: =B19&"," -> 510, | S19: =C19&"," -> 0, | T19: =D19 -> 300 | U19: D, | V19: =A19&"," -> 18, | W19: =IF(E19=1,"UX","") | X19: =IF(F19=1,"UY","") | Y19: =IF(G19=1,"UY","") -> UY | Z19: F, | AA19: =Q19 -> 18, | AB19: FY, | AC19: =-(1.4*K19+1.5*N19) -> 0.873
A20: 19 | B20: 540 | C20: 0 | D20: 300 | E20: 0 | F20: 0 | G20: 1 | H20: 900 | I20: 0 | J20: 0 | K20: =-H20*4.25/10000 -> -0.3825 | L20: 0 | M20: 0 | N20: =-H20*2.5/10000 -> -0.225 | P20: N, | Q20: =A20&"," -> 19, | R20: =B20&"," -> 540, | S20: =C20&"," -> 0, | T20: =D20 -> 300 | U20: D, | V20: =A20&"," -> 19, | W20: =IF(E20=1,"UX","") | X20: =IF(F20=1,"UY","") | Y20: =IF(G20=1,"UY","") -> UY | Z20: F, | AA20: =Q20 -> 19, | AB20: FY, | AC20: =-(1.4*K20+1.5*N20) -> 0.873
A21: 20 | B21: 570 | C21: 0 | D21: 300 | E21: 0 | F21: 0 | G21: 1 | H21: 900 | I21: 0 | J21: 0 | K21: =-H21*4.25/10000 -> -0.3825 | L21: 0 | M21: 0 | N21: =-H21*2.5/10000 -> -0.225 | P21: N, | Q21: =A21&"," -> 20, | R21: =B21&"," -> 570, | S21: =C21&"," -> 0, | T21: =D21 -> 300 | U21: D, | V21: =A21&"," -> 20, | W21: =IF(E21=1,"UX","") | X21: =IF(F21=1,"UY","") | Y21: =IF(G21=1,"UY","") -> UY | Z21: F, | AA21: =Q21 -> 20, | AB21: FY, | AC21: =-(1.4*K21+1.5*N21) -> 0.873
A22: 21 | B22: 600 | C22: 0 | D22: 300 | E22: 1 | F22: 1 | G22: 1 | H22: 900 | I22: 0 | J22: 0 | K22: =-H22*4.25/10000 -> -0.3825 | L22: 0 | M22: 0 | N22: =-H22*2.5/10000 -> -0.225 | P22: N, | Q22: =A22&"," -> 21, | R22: =B22&"," -> 600, | S22: =C22&"," -> 0, | T22: =D22 -> 300 | U22: D, | V22: =A22&"," -> 21, | W22: =IF(E22=1,"UX","") -> UX | X22: =IF(F22=1,"UY","") -> UY | Y22: =IF(G22=1,"UY,","") -> UY, | Z22: F, | AA22: =Q22 -> 21, | AB22: FY, | AC22: =-(1.4*K22+1.5*N22) -> 0.873
A23: 22 | B23: 0 | C23: 0 | D23: 270 | E23: 0 | F23: 0 | G23: 1 | H23: 900 | I23: 0 | J23: 0 | K23: =-H23*4.25/10000 -> -0.3825 | L23: 0 | M23: 0 | N23: =-H23*2.5/10000 -> -0.225 | P23: N, | Q23: =A23&"," -> 22, | R23: =B23&"," -> 0, | S23: =C23&"," -> 0, | T23: =D23 -> 270 | U23: D, | V23: =A23&"," -> 22, | W23: =IF(E23=1,"UX","") | X23: =IF(F23=1,"UY","") | Y23: =IF(G23=1,"UY","") -> UY | Z23: F, | AA23: =Q23 -> 22, | AB23: FY, | AC23: =-(1.4*K23+1.5*N23) -> 0.873
A24: 23 | B24: 30 | C24: 0 | D24: 270 | H24: 900 | I24: 0 | J24: 0 | K24: =-H24*4.25/10000 -> -0.3825 | L24: 0 | M24: 0 | N24: =-H24*2.5/10000 -> -0.225 | P24: N, | Q24: =A24&"," -> 23, | R24: =B24&"," -> 30, | S24: =C24&"," -> 0, | T24: =D24 -> 270 | U24: D, | V24: =A24&"," -> 23, | W24: =IF(E24=1,"UX","") | X24: =IF(F24=1,"UY","") | Y24: =IF(G24=1,"UY","") | Z24: F, | AA24: =Q24 -> 23, | AB24: FY, | AC24: =-(1.4*K24+1.5*N24) -> 0.873
A25: 24 | B25: 60 | C25: 0 | D25: 270 | H25: 900 | I25: 0 | J25: 0 | K25: =-H25*4.25/10000 -> -0.3825 | L25: 0 | M25: 0 | N25: =-H25*2.5/10000 -> -0.225 | P25: N, | Q25: =A25&"," -> 24, | R25: =B25&"," -> 60, | S25: =C25&"," -> 0, | T25: =D25 -> 270 | U25: D, | V25: =A25&"," -> 24, | W25: =IF(E25=1,"UX","") | X25: =IF(F25=1,"UY","") | Y25: =IF(G25=1,"UY","") | Z25: F, | AA25: =Q25 -> 24, | AB25: FY, | AC25: =-(1.4*K25+1.5*N25) -> 0.873
A26: 25 | B26: 90 | C26: 0 | D26: 270 | H26: 900 | I26: 0 | J26: 0 | K26: =-H26*4.25/10000 -> -0.3825 | L26: 0 | M26: 0 | N26: =-H26*2.5/10000 -> -0.225 | P26: N, | Q26: =A26&"," -> 25, | R26: =B26&"," -> 90, | S26: =C26&"," -> 0, | T26: =D26 -> 270 | U26: D, | V26: =A26&"," -> 25, | W26: =IF(E26=1,"UX","") | X26: =IF(F26=1,"UY","") | Y26: =IF(G26=1,"UY","") | Z26: F, | AA26: =Q26 -> 25, | AB26: FY, | AC26: =-(1.4*K26+1.5*N26) -> 0.873
A27: 26 | B27: 120 | C27: 0 | D27: 270 | H27: 900 | I27: 0 | J27: 0 | K27: =-H27*4.25/10000 -> -0.3825 | L27: 0 | M27: 0 | N27: =-H27*2.5/10000 -> -0.225 | P27: N, | Q27: =A27&"," -> 26, | R27: =B27&"," -> 120, | S27: =C27&"," -> 0, | T27: =D27 -> 270 | U27: D, | V27: =A27&"," -> 26, | W27: =IF(E27=1,"UX","") | X27: =IF(F27=1,"UY","") | Y27: =IF(G27=1,"UY","") | Z27: F, | AA27: =Q27 -> 26, | AB27: FY, | AC27: =-(1.4*K27+1.5*N27) -> 0.873
A28: 27 | B28: 150 | C28: 0 | D28: 270 | H28: 900 | I28: 0 | J28: 0 | K28: =-H28*4.25/10000 -> -0.3825 | L28: 0 | M28: 0 | N28: =-H28*2.5/10000 -> -0.225 | P28: N, | Q28: =A28&"," -> 27, | R28: =B28&"," -> 150, | S28: =C28&"," -> 0, | T28: =D28 -> 270 | U28: D, | V28: =A28&"," -> 27, | W28: =IF(E28=1,"UX","") | X28: =IF(F28=1,"UY","") | Y28: =IF(G28=1,"UY","") | Z28: F, | AA28: =Q28 -> 27, | AB28: FY, | AC28: =-(1.4*K28+1.5*N28) -> 0.873
A29: 28 | B29: 180 | C29: 0 | D29: 270 | H29: 900 | I29: 0 | J29: 0 | K29: =-H29*4.25/10000 -> -0.3825 | L29: 0 | M29: 0 | N29: =-H29*2.5/10000 -> -0.225 | P29: N, | Q29: =A29&"," -> 28, | R29: =B29&"," -> 180, | S29: =C29&"," -> 0, | T29: =D29 -> 270 | U29: D, | V29: =A29&"," -> 28, | W29: =IF(E29=1,"UX","") | X29: =IF(F29=1,"UZ","") | Y29: =IF(G29=1,"UY","") | Z29: F, | AA29: =Q29 -> 28, | AB29: FY, | AC29: =-(1.4*K29+1.5*N29) -> 0.873
A30: 29 | B30: 210 | C30: 0 | D30: 270 | H30: 900 | I30: 0 | J30: 0 | K30: =-H30*4.25/10000 -> -0.3825 | L30: 0 | M30: 0 | N30: =-H30*2.5/10000 -> -0.225 | P30: N, | Q30: =A30&"," -> 29, | R30: =B30&"," -> 210, | S30: =C30&"," -> 0, | T30: =D30 -> 270 | U30: D, | V30: =A30&"," -> 29, | W30: =IF(E30=1,"UX","") | X30: =IF(F30=1,"UZ","") | Y30: =IF(G30=1,"UY","") | Z30: F, | AA30: =Q30 -> 29, | AB30: FY, | AC30: =-(1.4*K30+1.5*N30) -> 0.873
A31: 30 | B31: 240 | C31: 0 | D31: 270 | H31: 900 | I31: 0 | J31: 0 | K31: =-H31*4.25/10000 -> -0.3825 | L31: 0 | M31: 0 | N31: =-H31*2.5/10000 -> -0.225 | P31: N, | Q31: =A31&"," -> 30, | R31: =B31&"," -> 240, | S31: =C31&"," -> 0, | T31: =D31 -> 270 | U31: D, | V31: =A31&"," -> 30, | W31: =IF(E31=1,"UX","") | X31: =IF(F31=1,"UY","") | Y31: =IF(G31=1,"UY","") | Z31: F, | AA31: =Q31 -> 30, | AB31: FY, | AC31: =-(1.4*K31+1.5*N31) -> 0.873
A32: 31 | B32: 270 | C32: 0 | D32: 270 | H32: 900 | I32: 0 | J32: 0 | K32: =-H32*4.25/10000 -> -0.3825 | L32: 0 | M32: 0 | N32: =-H32*2.5/10000 -> -0.225 | P32: N, | Q32: =A32&"," -> 31, | R32: =B32&"," -> 270, | S32: =C32&"," -> 0, | T32: =D32 -> 270 | U32: D, | V32: =A32&"," -> 31, | W32: =IF(E32=1,"UX","") | X32: =IF(F32=1,"UY","") | Y32: =IF(G32=1,"UY","") | Z32: F, | AA32: =Q32 -> 31, | AB32: FY, | AC32: =-(1.4*K32+1.5*N32) -> 0.873
A33: 32 | B33: 300 | C33: 0 | D33: 270 | H33: 900 | I33: 0 | J33: 0 | K33: =-H33*4.25/10000 -> -0.3825 | L33: 0 | M33: 0 | N33: =-H33*2.5/10000 -> -0.225 | P33: N, | Q33: =A33&"," -> 32, | R33: =B33&"," -> 300, | S33: =C33&"," -> 0, | T33: =D33 -> 270 | U33: D, | V33: =A33&"," -> 32, | W33: =IF(E33=1,"UX","") | X33: =IF(F33=1,"UY","") | Y33: =IF(G33=1,"UY","") | Z33: F, | AA33: =Q33 -> 32, | AB33: FY, | AC33: =-(1.4*K33+1.5*N33) -> 0.873
A34: 33 | B34: 330 | C34: 0 | D34: 270 | H34: 900 | I34: 0 | J34: 0 | K34: =-H34*4.25/10000 -> -0.3825 | L34: 0 | M34: 0 | N34: =-H34*2.5/10000 -> -0.225 | P34: N, | Q34: =A34&"," -> 33, | R34: =B34&"," -> 330, | S34: =C34&"," -> 0, | T34: =D34 -> 270 | U34: D, | V34: =A34&"," -> 33, | W34: =IF(E34=1,"UX","") | X34: =IF(F34=1,"UY","") | Y34: =IF(G34=1,"UY","") | Z34: F, | AA34: =Q34 -> 33, | AB34: FY, | AC34: =-(1.4*K34+1.5*N34) -> 0.873
A35: 34 | B35: 360 | C35: 0 | D35: 270 | H35: 900 | I35: 0 | J35: 0 | K35: =-H35*4.25/10000 -> -0.3825 | L35: 0 | M35: 0 | N35: =-H35*2.5/10000 -> -0.225 | P35: N, | Q35: =A35&"," -> 34, | R35: =B35&"," -> 360, | S35: =C35&"," -> 0, | T35: =D35 -> 270 | U35: D, | V35: =A35&"," -> 34, | W35: =IF(E35=1,"UX","") | X35: =IF(F35=1,"UY","") | Y35: =IF(G35=1,"UY","") | Z35: F, | AA35: =Q35 -> 34, | AB35: FY, | AC35: =-(1.4*K35+1.5*N35) -> 0.873
A36: 35 | B36: 390 | C36: 0 | D36: 270 | H36: 900 | I36: 0 | J36: 0 | K36: =-H36*4.25/10000 -> -0.3825 | L36: 0 | M36: 0 | N36: =-H36*2.5/10000 -> -0.225 | P36: N, | Q36: =A36&"," -> 35, | R36: =B36&"," -> 390, | S36: =C36&"," -> 0, | T36: =D36 -> 270 | U36: D, | V36: =A36&"," -> 35, | W36: =IF(E36=1,"UX","") | X36: =IF(F36=1,"UY","") | Y36: =IF(G36=1,"UY","") | Z36: F, | AA36: =Q36 -> 35, | AB36: FY, | AC36: =-(1.4*K36+1.5*N36) -> 0.873
A37: 36 | B37: 420 | C37: 0 | D37: 270 | H37: 900 | I37: 0 | J37: 0 | K37: =-H37*4.25/10000 -> -0.3825 | L37: 0 | M37: 0 | N37: =-H37*2.5/10000 -> -0.225 | P37: N, | Q37: =A37&"," -> 36, | R37: =B37&"," -> 420, | S37: =C37&"," -> 0, | T37: =D37 -> 270 | U37: D, | V37: =A37&"," -> 36, | W37: =IF(E37=1,"UX","") | X37: =IF(F37=1,"UY","") | Y37: =IF(G37=1,"UY","") | Z37: F, | AA37: =Q37 -> 36, | AB37: FY, | AC37: =-(1.4*K37+1.5*N37) -> 0.873
A38: 37 | B38: 450 | C38: 0 | D38: 270 | H38: 900 | I38: 0 | J38: 0 | K38: =-H38*4.25/10000 -> -0.3825 | L38: 0 | M38: 0 | N38: =-H38*2.5/10000 -> -0.225 | P38: N, | Q38: =A38&"," -> 37, | R38: =B38&"," -> 450, | S38: =C38&"," -> 0, | T38: =D38 -> 270 | U38: D, | V38: =A38&"," -> 37, | W38: =IF(E38=1,"UX","") | X38: =IF(F38=1,"UY","") | Y38: =IF(G38=1,"UY","") | Z38: F, | AA38: =Q38 -> 37, | AB38: FY, | AC38: =-(1.4*K38+1.5*N38) -> 0.873
A39: 38 | B39: 480 | C39: 0 | D39: 270 | H39: 900 | I39: 0 | J39: 0 | K39: =-H39*4.25/10000 -> -0.3825 | L39: 0 | M39: 0 | N39: =-H39*2.5/10000 -> -0.225 | P39: N, | Q39: =A39&"," -> 38, | R39: =B39&"," -> 480, | S39: =C39&"," -> 0, | T39: =D39 -> 270 | U39: D, | V39: =A39&"," -> 38, | W39: =IF(E39=1,"UX","") | X39: =IF(F39=1,"UY","") | Y39: =IF(G39=1,"UY","") | Z39: F, | AA39: =Q39 -> 38, | AB39: FY, | AC39: =-(1.4*K39+1.5*N39) -> 0.873
A40: 39 | B40: 510 | C40: 0 | D40: 270 | H40: 900 | I40: 0 | J40: 0 | K40: =-H40*4.25/10000 -> -0.3825 | L40: 0 | M40: 0 | N40: =-H40*2.5/10000 -> -0.225 | P40: N, | Q40: =A40&"," -> 39, | R40: =B40&"," -> 510, | S40: =C40&"," -> 0, | T40: =D40 -> 270 | U40: D, | V40: =A40&"," -> 39, | W40: =IF(E40=1,"UX","") | X40: =IF(F40=1,"UY","") | Y40: =IF(G40=1,"UY","") | Z40: F, | AA40: =Q40 -> 39, | AB40: FY, | AC40: =-(1.4*K40+1.5*N40) -> 0.873
...

Sheet elements
A1: element | B1: node_i | C1: node_j | D1: It | E1: If | F1: E | G1: G | H1: x1 | I1: y1 | J1: x2 | K1: y2 | L1: d | N1: k_rx | O1: k_ry | P1: k_z | R1: ELEMENT | S1: N | T1: i | U1: j
A2: 1 | B2: 1 | C2: 2 | D2: =E2*2 -> 10985 | E2: =(30*13^3)/12 -> 5492.5 | F2: 2380 | G2: =F2/(2*(1+0.2)) -> 991.66667 | H2: =VLOOKUP(B2,nodes!A:D,2,0) -> 0 | I2: =VLOOKUP(B2,nodes!A:D,4,0) -> 300 | J2: =VLOOKUP(C2,nodes!A:D,2,0) -> 30 | K2: =VLOOKUP(C2,nodes!A:D,4,0) -> 300 | L2: =((J2-H2)^2+(K2-I2)^2)^0.5 -> 30 | N2: =12*2380*60*(25^3)/(300*12) -> 7437500 | O2: =12*2380*25*(60^3)/(300*12) -> 42840000 | P2: =2380*25*60/300 -> 11900 | R2: EN, | S2: =A2&"," -> 1, | T2: =B2&"," -> 1, | U2: =C2 -> 2
A3: 2 | B3: 2 | C3: 3 | D3: =E3*2 -> 10985 | E3: =(30*13^3)/12 -> 5492.5 | F3: 2380 | G3: =F3/(2*(1+0.2)) -> 991.66667 | H3: =VLOOKUP(B3,nodes!A:D,2,0) -> 30 | I3: =VLOOKUP(B3,nodes!A:D,4,0) -> 300 | J3: =VLOOKUP(C3,nodes!A:D,2,0) -> 60 | K3: =VLOOKUP(C3,nodes!A:D,4,0) -> 300 | L3: =((J3-H3)^2+(K3-I3)^2)^0.5 -> 30 | N3: =12*2380*60*(25^3)/(300*12) -> 7437500 | O3: =12*2380*25*(60^3)/(300*12) -> 42840000 | P3: =2380*25*60/300 -> 11900 | R3: EN, | S3: =A3&"," -> 2, | T3: =B3&"," -> 2, | U3: =C3 -> 3
A4: 3 | B4: 3 | C4: 4 | D4: =E4*2 -> 10985 | E4: =(30*13^3)/12 -> 5492.5 | F4: 2380 | G4: =F4/(2*(1+0.2)) -> 991.66667 | H4: =VLOOKUP(B4,nodes!A:D,2,0) -> 60 | I4: =VLOOKUP(B4,nodes!A:D,4,0) -> 300 | J4: =VLOOKUP(C4,nodes!A:D,2,0) -> 90 | K4: =VLOOKUP(C4,nodes!A:D,4,0) -> 300 | L4: =((J4-H4)^2+(K4-I4)^2)^0.5 -> 30 | N4: =12*2380*60*(25^3)/(300*12) -> 7437500 | O4: =12*2380*25*(60^3)/(300*12) -> 42840000 | P4: =2380*25*60/300 -> 11900 | R4: EN, | S4: =A4&"," -> 3, | T4: =B4&"," -> 3, | U4: =C4 -> 4
A5: 4 | B5: 4 | C5: 5 | D5: =E5*2 -> 10985 | E5: =(30*13^3)/12 -> 5492.5 | F5: 2380 | G5: =F5/(2*(1+0.2)) -> 991.66667 | H5: =VLOOKUP(B5,nodes!A:D,2,0) -> 90 | I5: =VLOOKUP(B5,nodes!A:D,4,0) -> 300 | J5: =VLOOKUP(C5,nodes!A:D,2,0) -> 120 | K5: =VLOOKUP(C5,nodes!A:D,4,0) -> 300 | L5: =((J5-H5)^2+(K5-I5)^2)^0.5 -> 30 | N5: =12*2380*60*(25^3)/(300*12) -> 7437500 | O5: =12*2380*25*(60^3)/(300*12) -> 42840000 | P5: =2380*25*60/300 -> 11900 | R5: EN, | S5: =A5&"," -> 4, | T5: =B5&"," -> 4, | U5: =C5 -> 5
A6: 5 | B6: 5 | C6: 6 | D6: =E6*2 -> 10985 | E6: =(30*13^3)/12 -> 5492.5 | F6: 2380 | G6: =F6/(2*(1+0.2)) -> 991.66667 | H6: =VLOOKUP(B6,nodes!A:D,2,0) -> 120 | I6: =VLOOKUP(B6,nodes!A:D,4,0) -> 300 | J6: =VLOOKUP(C6,nodes!A:D,2,0) -> 150 | K6: =VLOOKUP(C6,nodes!A:D,4,0) -> 300 | L6: =((J6-H6)^2+(K6-I6)^2)^0.5 -> 30 | N6: =12*2380*60*(25^3)/(300*12) -> 7437500 | O6: =12*2380*25*(60^3)/(300*12) -> 42840000 | P6: =2380*25*60/300 -> 11900 | R6: EN, | S6: =A6&"," -> 5, | T6: =B6&"," -> 5, | U6: =C6 -> 6
A7: 6 | B7: 6 | C7: 7 | D7: =E7*2 -> 10985 | E7: =(30*13^3)/12 -> 5492.5 | F7: 2380 | G7: =F7/(2*(1+0.2)) -> 991.66667 | H7: =VLOOKUP(B7,nodes!A:D,2,0) -> 150 | I7: =VLOOKUP(B7,nodes!A:D,4,0) -> 300 | J7: =VLOOKUP(C7,nodes!A:D,2,0) -> 180 | K7: =VLOOKUP(C7,nodes!A:D,4,0) -> 300 | L7: =((J7-H7)^2+(K7-I7)^2)^0.5 -> 30 | N7: =12*2380*60*(25^3)/(300*12) -> 7437500 | O7: =12*2380*25*(60^3)/(300*12) -> 42840000 | P7: =2380*25*60/300 -> 11900 | R7: EN, | S7: =A7&"," -> 6, | T7: =B7&"," -> 6, | U7: =C7 -> 7
A8: 7 | B8: 7 | C8: 8 | D8: =E8*2 -> 10985 | E8: =(30*13^3)/12 -> 5492.5 | F8: 2380 | G8: =F8/(2*(1+0.2)) -> 991.66667 | H8: =VLOOKUP(B8,nodes!A:D,2,0) -> 180 | I8: =VLOOKUP(B8,nodes!A:D,4,0) -> 300 | J8: =VLOOKUP(C8,nodes!A:D,2,0) -> 210 | K8: =VLOOKUP(C8,nodes!A:D,4,0) -> 300 | L8: =((J8-H8)^2+(K8-I8)^2)^0.5 -> 30 | N8: =12*2380*60*(25^3)/(300*12) -> 7437500 | O8: =12*2380*25*(60^3)/(300*12) -> 42840000 | P8: =2380*25*60/300 -> 11900 | R8: EN, | S8: =A8&"," -> 7, | T8: =B8&"," -> 7, | U8: =C8 -> 8
A9: 8 | B9: 8 | C9: 9 | D9: =E9*2 -> 10985 | E9: =(30*13^3)/12 -> 5492.5 | F9: 2380 | G9: =F9/(2*(1+0.2)) -> 991.66667 | H9: =VLOOKUP(B9,nodes!A:D,2,0) -> 210 | I9: =VLOOKUP(B9,nodes!A:D,4,0) -> 300 | J9: =VLOOKUP(C9,nodes!A:D,2,0) -> 240 | K9: =VLOOKUP(C9,nodes!A:D,4,0) -> 300 | L9: =((J9-H9)^2+(K9-I9)^2)^0.5 -> 30 | N9: =12*2380*60*(25^3)/(300*12) -> 7437500 | O9: =12*2380*25*(60^3)/(300*12) -> 42840000 | P9: =2380*25*60/300 -> 11900 | R9: EN, | S9: =A9&"," -> 8, | T9: =B9&"," -> 8, | U9: =C9 -> 9
A10: 9 | B10: 9 | C10: 10 | D10: =E10*2 -> 10985 | E10: =(30*13^3)/12 -> 5492.5 | F10: 2380 | G10: =F10/(2*(1+0.2)) -> 991.66667 | H10: =VLOOKUP(B10,nodes!A:D,2,0) -> 240 | I10: =VLOOKUP(B10,nodes!A:D,4,0) -> 300 | J10: =VLOOKUP(C10,nodes!A:D,2,0) -> 270 | K10: =VLOOKUP(C10,nodes!A:D,4,0) -> 300 | L10: =((J10-H10)^2+(K10-I10)^2)^0.5 -> 30 | N10: =12*2380*60*(25^3)/(300*12) -> 7437500 | O10: =12*2380*25*(60^3)/(300*12) -> 42840000 | P10: =2380*25*60/300 -> 11900 | R10: EN, | S10: =A10&"," -> 9, | T10: =B10&"," -> 9, | U10: =C10 -> 10
A11: 10 | B11: 10 | C11: 11 | D11: =E11*2 -> 10985 | E11: =(30*13^3)/12 -> 5492.5 | F11: 2380 | G11: =F11/(2*(1+0.2)) -> 991.66667 | H11: =VLOOKUP(B11,nodes!A:D,2,0) -> 270 | I11: =VLOOKUP(B11,nodes!A:D,4,0) -> 300 | J11: =VLOOKUP(C11,nodes!A:D,2,0) -> 300 | K11: =VLOOKUP(C11,nodes!A:D,4,0) -> 300 | L11: =((J11-H11)^2+(K11-I11)^2)^0.5 -> 30 | N11: =12*2380*60*(25^3)/(300*12) -> 7437500 | O11: =12*2380*25*(60^3)/(300*12) -> 42840000 | P11: =2380*25*60/300 -> 11900 | R11: EN, | S11: =A11&"," -> 10, | T11: =B11&"," -> 10, | U11: =C11 -> 11
A12: 11 | B12: 11 | C12: 12 | D12: =E12*2 -> 10985 | E12: =(30*13^3)/12 -> 5492.5 | F12: 2380 | G12: =F12/(2*(1+0.2)) -> 991.66667 | H12: =VLOOKUP(B12,nodes!A:D,2,0) -> 300 | I12: =VLOOKUP(B12,nodes!A:D,4,0) -> 300 | J12: =VLOOKUP(C12,nodes!A:D,2,0) -> 330 | K12: =VLOOKUP(C12,nodes!A:D,4,0) -> 300 | L12: =((J12-H12)^2+(K12-I12)^2)^0.5 -> 30 | N12: =12*2380*60*(25^3)/(300*12) -> 7437500 | O12: =12*2380*25*(60^3)/(300*12) -> 42840000 | P12: =2380*25*60/300 -> 11900 | R12: EN, | S12: =A12&"," -> 11, | T12: =B12&"," -> 11, | U12: =C12 -> 12
A13: 12 | B13: 12 | C13: 13 | D13: =E13*2 -> 10985 | E13: =(30*13^3)/12 -> 5492.5 | F13: 2380 | G13: =F13/(2*(1+0.2)) -> 991.66667 | H13: =VLOOKUP(B13,nodes!A:D,2,0) -> 330 | I13: =VLOOKUP(B13,nodes!A:D,4,0) -> 300 | J13: =VLOOKUP(C13,nodes!A:D,2,0) -> 360 | K13: =VLOOKUP(C13,nodes!A:D,4,0) -> 300 | L13: =((J13-H13)^2+(K13-I13)^2)^0.5 -> 30 | N13: =12*2380*60*(25^3)/(300*12) -> 7437500 | O13: =12*2380*25*(60^3)/(300*12) -> 42840000 | P13: =2380*25*60/300 -> 11900 | R13: EN, | S13: =A13&"," -> 12, | T13: =B13&"," -> 12, | U13: =C13 -> 13
... A431: 430 | B431: 210 | C431: 231 | D431: =E431*2 -> 10985 | E431: =(30*13^3)/12 -> 5492.5 | F431: 2380 | G431: =F431/(2*(1+0.2)) -> 991.66667 | H431: =VLOOKUP(B431,nodes!A:D,2,0) -> 600 | I431: =VLOOKUP(B431,nodes!A:D,4,0) -> 30 | J431: =VLOOKUP(C431,nodes!A:D,2,0) -> 600 | K431: =VLOOKUP(C431,nodes!A:D,4,0) -> 0 | L431: =((J431-H431)^2+(K431-I431)^2)^0.5 -> 30 | N431: =12*2380*60*(25^3)/(300*12) -> 7437500 | O431: =12*2380*25*(60^3)/(300*12) -> 42840000 | P431: =2380*25*60/300 -> 11900 | R431: EN, | S431: =A431&"," -> 430, | T431: =B431&"," -> 210, | U431: =C431 -> 231

Sheet It_corrD
A1: element | B1: node_i | C1: node_j | D1: It | E1: If | F1: E | G1: G | H1: x1 | I1: y1 | J1: x2 | K1: y2 | L1: d | N1: k_rx | O1: k_ry | P1: k_z
A2: 1 | B2: 1 | C2: 2 | D2: 12280 | E2: =(30*13^3)/12 -> 5492.5 | F2: 2380 | G2: =F2/(2*(1+0.2)) -> 991.66667 | H2: =VLOOKUP(B2,nodes!A:D,2,0) -> 0 | I2: =VLOOKUP(B2,nodes!A:D,4,0) -> 300 | J2: =VLOOKUP(C2,nodes!A:D,2,0) -> 30 | K2: =VLOOKUP(C2,nodes!A:D,4,0) -> 300 | L2: =((J2-H2)^2+(K2-I2)^2)^0.5 -> 30 | N2: =12*2380*60*(25^3)/(300*12) -> 7437500 | O2: =12*2380*25*(60^3)/(300*12) -> 42840000 | P2: =2380*25*60/300 -> 11900
A3: 2 | B3: 2 | C3: 3 | D3: 12280 | E3: =(30*13^3)/12 -> 5492.5 | F3: 2380 | G3: =F3/(2*(1+0.2)) -> 991.66667 | H3: =VLOOKUP(B3,nodes!A:D,2,0) -> 30 | I3: =VLOOKUP(B3,nodes!A:D,4,0) -> 300 | J3: =VLOOKUP(C3,nodes!A:D,2,0) -> 60 | K3: =VLOOKUP(C3,nodes!A:D,4,0) -> 300 | L3: =((J3-H3)^2+(K3-I3)^2)^0.5 -> 30 | N3: =12*2380*60*(25^3)/(300*12) -> 7437500 | O3: =12*2380*25*(60^3)/(300*12) -> 42840000 | P3: =2380*25*60/300 -> 11900
A4: 3 | B4: 3 | C4: 4 | D4: 12280 | E4: =(30*13^3)/12 -> 5492.5 | F4: 2380 | G4: =F4/(2*(1+0.2)) -> 991.66667 | H4: =VLOOKUP(B4,nodes!A:D,2,0) -> 60 | I4: =VLOOKUP(B4,nodes!A:D,4,0) -> 300 | J4: =VLOOKUP(C4,nodes!A:D,2,0) -> 90 | K4: =VLOOKUP(C4,nodes!A:D,4,0) -> 300 | L4: =((J4-H4)^2+(K4-I4)^2)^0.5 -> 30 | N4: =12*2380*60*(25^3)/(300*12) -> 7437500 | O4: =12*2380*25*(60^3)/(300*12) -> 42840000 | P4: =2380*25*60/300 -> 11900
A5: 4 | B5: 4 | C5: 5 | D5: 12280 | E5: =(30*13^3)/12 -> 5492.5 | F5: 2380 | G5: =F5/(2*(1+0.2)) -> 991.66667 | H5: =VLOOKUP(B5,nodes!A:D,2,0) -> 90 | I5: =VLOOKUP(B5,nodes!A:D,4,0) -> 300 | J5: =VLOOKUP(C5,nodes!A:D,2,0) -> 120 | K5: =VLOOKUP(C5,nodes!A:D,4,0) -> 300 | L5: =((J5-H5)^2+(K5-I5)^2)^0.5 -> 30 | N5: =12*2380*60*(25^3)/(300*12) -> 7437500 | O5: =12*2380*25*(60^3)/(300*12) -> 42840000 | P5: =2380*25*60/300 -> 11900
A6: 5 | B6: 5 | C6: 6 | D6: 12280 | E6: =(30*13^3)/12 -> 5492.5 | F6: 2380 | G6: =F6/(2*(1+0.2)) -> 991.66667 | H6: =VLOOKUP(B6,nodes!A:D,2,0) -> 120 | I6: =VLOOKUP(B6,nodes!A:D,4,0) -> 300 | J6: =VLOOKUP(C6,nodes!A:D,2,0) -> 150 | K6: =VLOOKUP(C6,nodes!A:D,4,0) -> 300 | L6: =((J6-H6)^2+(K6-I6)^2)^0.5 -> 30 | N6: =12*2380*60*(25^3)/(300*12) -> 7437500 | O6: =12*2380*25*(60^3)/(300*12) -> 42840000 | P6: =2380*25*60/300 -> 11900
A7: 6 | B7: 6 | C7: 7 | D7: 12280 | E7: =(30*13^3)/12 -> 5492.5 | F7: 2380 | G7: =F7/(2*(1+0.2)) -> 991.66667 | H7: =VLOOKUP(B7,nodes!A:D,2,0) -> 150 | I7: =VLOOKUP(B7,nodes!A:D,4,0) -> 300 | J7: =VLOOKUP(C7,nodes!A:D,2,0) -> 180 | K7: =VLOOKUP(C7,nodes!A:D,4,0) -> 300 | L7: =((J7-H7)^2+(K7-I7)^2)^0.5 -> 30 | N7: =12*2380*60*(25^3)/(300*12) -> 7437500 | O7: =12*2380*25*(60^3)/(300*12) -> 42840000 | P7: =2380*25*60/300 -> 11900
A8: 7 | B8: 7 | C8: 8 | D8: 12280 | E8: =(30*13^3)/12 -> 5492.5 | F8: 2380 | G8: =F8/(2*(1+0.2)) -> 991.66667 | H8: =VLOOKUP(B8,nodes!A:D,2,0) -> 180 | I8: =VLOOKUP(B8,nodes!A:D,4,0) -> 300 | J8: =VLOOKUP(C8,nodes!A:D,2,0) -> 210 | K8: =VLOOKUP(C8,nodes!A:D,4,0) -> 300 | L8: =((J8-H8)^2+(K8-I8)^2)^0.5 -> 30 | N8: =12*2380*60*(25^3)/(300*12) -> 7437500 | O8: =12*2380*25*(60^3)/(300*12) -> 42840000 | P8: =2380*25*60/300 -> 11900
A9: 8 | B9: 8 | C9: 9 | D9: 12280 | E9: =(30*13^3)/12 -> 5492.5 | F9: 2380 | G9: =F9/(2*(1+0.2)) -> 991.66667 | H9: =VLOOKUP(B9,nodes!A:D,2,0) -> 210 | I9: =VLOOKUP(B9,nodes!A:D,4,0) -> 300 | J9: =VLOOKUP(C9,nodes!A:D,2,0) -> 240 | K9: =VLOOKUP(C9,nodes!A:D,4,0) -> 300 | L9: =((J9-H9)^2+(K9-I9)^2)^0.5 -> 30 | N9: =12*2380*60*(25^3)/(300*12) -> 7437500 | O9: =12*2380*25*(60^3)/(300*12) -> 42840000 | P9: =2380*25*60/300 -> 11900
A10: 9 | B10: 9 | C10: 10 | D10: 12280 | E10: =(30*13^3)/12 -> 5492.5 | F10: 2380 | G10: =F10/(2*(1+0.2)) -> 991.66667 | H10: =VLOOKUP(B10,nodes!A:D,2,0) -> 240 | I10: =VLOOKUP(B10,nodes!A:D,4,0) -> 300 | J10: =VLOOKUP(C10,nodes!A:D,2,0) -> 270 | K10: =VLOOKUP(C10,nodes!A:D,4,0) -> 300 | L10: =((J10-H10)^2+(K10-I10)^2)^0.5 -> 30 | N10: =12*2380*60*(25^3)/(300*12) -> 7437500 | O10: =12*2380*25*(60^3)/(300*12) -> 42840000 | P10: =2380*25*60/300 -> 11900
A11: 10 | B11: 10 | C11: 11 | D11: 12280 | E11: =(30*13^3)/12 -> 5492.5 | F11: 2380 | G11: =F11/(2*(1+0.2)) -> 991.66667 | H11: =VLOOKUP(B11,nodes!A:D,2,0) -> 270 | I11: =VLOOKUP(B11,nodes!A:D,4,0) -> 300 | J11: =VLOOKUP(C11,nodes!A:D,2,0) -> 300 | K11: =VLOOKUP(C11,nodes!A:D,4,0) -> 300 | L11: =((J11-H11)^2+(K11-I11)^2)^0.5 -> 30 | N11: =12*2380*60*(25^3)/(300*12) -> 7437500 | O11: =12*2380*25*(60^3)/(300*12) -> 42840000 | P11: =2380*25*60/300 -> 11900
A12: 11 | B12: 11 | C12: 12 | D12: 12280 | E12: =(30*13^3)/12 -> 5492.5 | F12: 2380 | G12: =F12/(2*(1+0.2)) -> 991.66667 | H12: =VLOOKUP(B12,nodes!A:D,2,0) -> 300 | I12: =VLOOKUP(B12,nodes!A:D,4,0) -> 300 | J12: =VLOOKUP(C12,nodes!A:D,2,0) -> 330 | K12: =VLOOKUP(C12,nodes!A:D,4,0) -> 300 | L12: =((J12-H12)^2+(K12-I12)^2)^0.5 -> 30 | N12: =12*2380*60*(25^3)/(300*12) -> 7437500 | O12: =12*2380*25*(60^3)/(300*12) -> 42840000 | P12: =2380*25*60/300 -> 11900
A13: 12 | B13: 12 | C13: 13 | D13: 12280 | E13: =(30*13^3)/12 -> 5492.5 | F13: 2380 | G13: =F13/(2*(1+0.2)) -> 991.66667 | H13: =VLOOKUP(B13,nodes!A:D,2,0) -> 330 | I13: =VLOOKUP(B13,nodes!A:D,4,0) -> 300 | J13: =VLOOKUP(C13,nodes!A:D,2,0) -> 360 | K13: =VLOOKUP(C13,nodes!A:D,4,0) -> 300 | L13: =((J13-H13)^2+(K13-I13)^2)^0.5 -> 30 | N13: =12*2380*60*(25^3)/(300*12) -> 7437500 | O13: =12*2380*25*(60^3)/(300*12) -> 42840000 | P13: =2380*25*60/300 -> 11900
... A431: 430 | B431: 210 | C431: 231 | D431: 12280 | E431: =(30*13^3)/12 -> 5492.5 | F431: 2380 | G431: =F431/(2*(1+0.2)) -> 991.66667 | H431: =VLOOKUP(B431,nodes!A:D,2,0) -> 600 | I431: =VLOOKUP(B431,nodes!A:D,4,0) -> 30 | J431: =VLOOKUP(C431,nodes!A:D,2,0) -> 600 | K431: =VLOOKUP(C431,nodes!A:D,4,0) -> 0 | L431: =((J431-H431)^2+(K431-I431)^2)^0.5 -> 30 | N431: =12*2380*60*(25^3)/(300*12) -> 7437500 | O431: =12*2380*25*(60^3)/(300*12) -> 42840000 | P431: =2380*25*60/300 -> 11900

Sheet It_corrM
A1: element | B1: node_i | C1: node_j | D1: It | E1: If | F1: E | G1: G | H1: x1 | I1: y1 | J1: x2 | K1: y2 | L1: d | N1: k_rx | O1: k_ry | P1: k_z
A2: 1 | B2: 1 | C2: 2 | D2: 11140 | E2: =(30*13^3)/12 -> 5492.5 | F2: 2380 | G2: =F2/(2*(1+0.2)) -> 991.66667 | H2: =VLOOKUP(B2,nodes!A:D,2,0) -> 0 | I2: =VLOOKUP(B2,nodes!A:D,4,0) -> 300 | J2: =VLOOKUP(C2,nodes!A:D,2,0) -> 30 | K2: =VLOOKUP(C2,nodes!A:D,4,0) -> 300 | L2: =((J2-H2)^2+(K2-I2)^2)^0.5 -> 30 | N2: =12*2380*60*(25^3)/(300*12) -> 7437500 | O2: =12*2380*25*(60^3)/(300*12) -> 42840000 | P2: =2380*25*60/300 -> 11900
A3: 2 | B3: 2 | C3: 3 | D3: 11140 | E3: =(30*13^3)/12 -> 5492.5 | F3: 2380 | G3: =F3/(2*(1+0.2)) -> 991.66667 | H3: =VLOOKUP(B3,nodes!A:D,2,0) -> 30 | I3: =VLOOKUP(B3,nodes!A:D,4,0) -> 300 | J3: =VLOOKUP(C3,nodes!A:D,2,0) -> 60 | K3: =VLOOKUP(C3,nodes!A:D,4,0) -> 300 | L3: =((J3-H3)^2+(K3-I3)^2)^0.5 -> 30 | N3: =12*2380*60*(25^3)/(300*12) -> 7437500 | O3: =12*2380*25*(60^3)/(300*12) -> 42840000 | P3: =2380*25*60/300 -> 11900
A4: 3 | B4: 3 | C4: 4 | D4: 11140 | E4: =(30*13^3)/12 -> 5492.5 | F4: 2380 | G4: =F4/(2*(1+0.2)) -> 991.66667 | H4: =VLOOKUP(B4,nodes!A:D,2,0) -> 60 | I4: =VLOOKUP(B4,nodes!A:D,4,0) -> 300 | J4: =VLOOKUP(C4,nodes!A:D,2,0) -> 90 | K4: =VLOOKUP(C4,nodes!A:D,4,0) -> 300 | L4: =((J4-H4)^2+(K4-I4)^2)^0.5 -> 30 | N4: =12*2380*60*(25^3)/(300*12) -> 7437500 | O4: =12*2380*25*(60^3)/(300*12) -> 42840000 | P4: =2380*25*60/300 -> 11900
A5: 4 | B5: 4 | C5: 5 | D5: 11140 | E5: =(30*13^3)/12 -> 5492.5 | F5: 2380 | G5: =F5/(2*(1+0.2)) -> 991.66667 | H5: =VLOOKUP(B5,nodes!A:D,2,0) -> 90 | I5: =VLOOKUP(B5,nodes!A:D,4,0) -> 300 | J5: =VLOOKUP(C5,nodes!A:D,2,0) -> 120 | K5: =VLOOKUP(C5,nodes!A:D,4,0) -> 300 | L5: =((J5-H5)^2+(K5-I5)^2)^0.5 -> 30 | N5: =12*2380*60*(25^3)/(300*12) -> 7437500 | O5: =12*2380*25*(60^3)/(300*12) -> 42840000 | P5: =2380*25*60/300 -> 11900
A6: 5 | B6: 5 | C6: 6 | D6: 11140 | E6: =(30*13^3)/12 -> 5492.5 | F6: 2380 | G6: =F6/(2*(1+0.2)) -> 991.66667 | H6: =VLOOKUP(B6,nodes!A:D,2,0) -> 120 | I6: =VLOOKUP(B6,nodes!A:D,4,0) -> 300 | J6: =VLOOKUP(C6,nodes!A:D,2,0) -> 150 | K6: =VLOOKUP(C6,nodes!A:D,4,0) -> 300 | L6: =((J6-H6)^2+(K6-I6)^2)^0.5 -> 30 | N6: =12*2380*60*(25^3)/(300*12) -> 7437500 | O6: =12*2380*25*(60^3)/(300*12) -> 42840000 | P6: =2380*25*60/300 -> 11900
A7: 6 | B7: 6 | C7: 7 | D7: 11140 | E7: =(30*13^3)/12 -> 5492.5 | F7: 2380 | G7: =F7/(2*(1+0.2)) -> 991.66667 | H7: =VLOOKUP(B7,nodes!A:D,2,0) -> 150 | I7: =VLOOKUP(B7,nodes!A:D,4,0) -> 300 | J7: =VLOOKUP(C7,nodes!A:D,2,0) -> 180 | K7: =VLOOKUP(C7,nodes!A:D,4,0) -> 300 | L7: =((J7-H7)^2+(K7-I7)^2)^0.5 -> 30 | N7: =12*2380*60*(25^3)/(300*12) -> 7437500 | O7: =12*2380*25*(60^3)/(300*12) -> 42840000 | P7: =2380*25*60/300 -> 11900
A8: 7 | B8: 7 | C8: 8 | D8: 11140 | E8: =(30*13^3)/12 -> 5492.5 | F8: 2380 | G8: =F8/(2*(1+0.2)) -> 991.66667 | H8: =VLOOKUP(B8,nodes!A:D,2,0) -> 180 | I8: =VLOOKUP(B8,nodes!A:D,4,0) -> 300 | J8: =VLOOKUP(C8,nodes!A:D,2,0) -> 210 | K8: =VLOOKUP(C8,nodes!A:D,4,0) -> 300 | L8: =((J8-H8)^2+(K8-I8)^2)^0.5 -> 30 | N8: =12*2380*60*(25^3)/(300*12) -> 7437500 | O8: =12*2380*25*(60^3)/(300*12) -> 42840000 | P8: =2380*25*60/300 -> 11900
A9: 8 | B9: 8 | C9: 9 | D9: 11140 | E9: =(30*13^3)/12 -> 5492.5 | F9: 2380 | G9: =F9/(2*(1+0.2)) -> 991.66667 | H9: =VLOOKUP(B9,nodes!A:D,2,0) -> 210 | I9: =VLOOKUP(B9,nodes!A:D,4,0) -> 300 | J9: =VLOOKUP(C9,nodes!A:D,2,0) -> 240 | K9: =VLOOKUP(C9,nodes!A:D,4,0) -> 300 | L9: =((J9-H9)^2+(K9-I9)^2)^0.5 -> 30 | N9: =12*2380*60*(25^3)/(300*12) -> 7437500 | O9: =12*2380*25*(60^3)/(300*12) -> 42840000 | P9: =2380*25*60/300 -> 11900
A10: 9 | B10: 9 | C10: 10 | D10: 11140 | E10: =(30*13^3)/12 -> 5492.5 | F10: 2380 | G10: =F10/(2*(1+0.2)) -> 991.66667 | H10: =VLOOKUP(B10,nodes!A:D,2,0) -> 240 | I10: =VLOOKUP(B10,nodes!A:D,4,0) -> 300 | J10: =VLOOKUP(C10,nodes!A:D,2,0) -> 270 | K10: =VLOOKUP(C10,nodes!A:D,4,0) -> 300 | L10: =((J10-H10)^2+(K10-I10)^2)^0.5 -> 30 | N10: =12*2380*60*(25^3)/(300*12) -> 7437500 | O10: =12*2380*25*(60^3)/(300*12) -> 42840000 | P10: =2380*25*60/300 -> 11900
A11: 10 | B11: 10 | C11: 11 | D11: 11140 | E11: =(30*13^3)/12 -> 5492.5 | F11: 2380 | G11: =F11/(2*(1+0.2)) -> 991.66667 | H11: =VLOOKUP(B11,nodes!A:D,2,0) -> 270 | I11: =VLOOKUP(B11,nodes!A:D,4,0) -> 300 | J11: =VLOOKUP(C11,nodes!A:D,2,0) -> 300 | K11: =VLOOKUP(C11,nodes!A:D,4,0) -> 300 | L11: =((J11-H11)^2+(K11-I11)^2)^0.5 -> 30 | N11: =12*2380*60*(25^3)/(300*12) -> 7437500 | O11: =12*2380*25*(60^3)/(300*12) -> 42840000 | P11: =2380*25*60/300 -> 11900
A12: 11 | B12: 11 | C12: 12 | D12: 11140 | E12: =(30*13^3)/12 -> 5492.5 | F12: 2380 | G12: =F12/(2*(1+0.2)) -> 991.66667 | H12: =VLOOKUP(B12,nodes!A:D,2,0) -> 300 | I12: =VLOOKUP(B12,nodes!A:D,4,0) -> 300 | J12: =VLOOKUP(C12,nodes!A:D,2,0) -> 330 | K12: =VLOOKUP(C12,nodes!A:D,4,0) -> 300 | L12: =((J12-H12)^2+(K12-I12)^2)^0.5 -> 30 | N12: =12*2380*60*(25^3)/(300*12) -> 7437500 | O12: =12*2380*25*(60^3)/(300*12) -> 42840000 | P12: =2380*25*60/300 -> 11900
A13: 12 | B13: 12 | C13: 13 | D13: 11140 | E13: =(30*13^3)/12 -> 5492.5 | F13: 2380 | G13: =F13/(2*(1+0.2)) -> 991.66667 | H13: =VLOOKUP(B13,nodes!A:D,2,0) -> 330 | I13: =VLOOKUP(B13,nodes!A:D,4,0) -> 300 | J13: =VLOOKUP(C13,nodes!A:D,2,0) -> 360 | K13: =VLOOKUP(C13,nodes!A:D,4,0) -> 300 | L13: =((J13-H13)^2+(K13-I13)^2)^0.5 -> 30 | N13: =12*2380*60*(25^3)/(300*12) -> 7437500 | O13: =12*2380*25*(60^3)/(300*12) -> 42840000 | P13: =2380*25*60/300 -> 11900
... A431: 430 | B431: 210 | C431: 231 | D431: 11140 | E431: =(30*13^3)/12 -> 5492.5 | F431: 2380 | G431: =F431/(2*(1+0.2)) -> 991.66667 | H431: =VLOOKUP(B431,nodes!A:D,2,0) -> 600 | I431: =VLOOKUP(B431,nodes!A:D,4,0) -> 30 | J431: =VLOOKUP(C431,nodes!A:D,2,0) -> 600 | K431: =VLOOKUP(C431,nodes!A:D,4,0) -> 0 | L431: =((J431-H431)^2+(K431-I431)^2)^0.5 -> 30 | N431: =12*2380*60*(25^3)/(300*12) -> 7437500 | O431: =12*2380*25*(60^3)/(300*12) -> 42840000 | P431: =2380*25*60/300 -> 11900
